<?xml version='1.0'?>
<sdf version='1.7'>
  <world name="car_world">
        <physics name="1ms" type="ignored">
            <max_step_size>0.001</max_step_size>
            <real_time_factor>1.0</real_time_factor>
        </physics>
        <plugin
            filename="libignition-gazebo-physics-system.so"
            name="ignition::gazebo::systems::Physics">
        </plugin>
        <plugin
            filename="libignition-gazebo-user-commands-system.so"
            name="ignition::gazebo::systems::UserCommands">
        </plugin>
        <plugin
            filename="libignition-gazebo-scene-broadcaster-system.so"
            name="ignition::gazebo::systems::SceneBroadcaster">
        </plugin>
        <plugin
          filename="ignition-gazebo-buoyancy-system"
          name="ignition::gazebo::systems::Buoyancy">
          <uniform_fluid_density>1000</uniform_fluid_density>
        </plugin>

        <!--
        <plugin
          filename="ignition-gazebo-thruster-system"
          name="ignition::gazebo::systems::Thruster">
          <namespace>tethys</namespace>
          <joint_name>propeller_joint</joint_name>
          <thrust_coefficient>0.004422</thrust_coefficient>
          <fluid_density>1000</fluid_density>
          <propeller_diameter>0.2</propeller_diameter>
        </plugin>
        -->
      


        <gui fullscreen="0">

            <!-- 3D scene -->
            <plugin filename="GzScene3D" name="3D View">
                <ignition-gui>
                <title>3D View</title>
                <property type="bool" key="showTitleBar">false</property>
                <property type="string" key="state">docked</property>
                </ignition-gui>

                <engine>ogre2</engine>
                <scene>scene</scene>
                <ambient_light>0.4 0.4 0.4</ambient_light>
                <background_color>0.8 0.8 0.8</background_color>
            </plugin>

            <!-- World control -->
            <plugin filename="WorldControl" name="World control">
                <ignition-gui>
                <title>World control</title>
                <property type="bool" key="showTitleBar">false</property>
                <property type="bool" key="resizable">false</property>
                <property type="double" key="height">72</property>
                <property type="double" key="width">121</property>
                <property type="double" key="z">1</property>

                <property type="string" key="state">floating</property>
                <anchors target="3D View">
                    <line own="left" target="left"/>
                    <line own="bottom" target="bottom"/>
                </anchors>
                </ignition-gui>

                <play_pause>true</play_pause>
                <step>true</step>
                <start_paused>true</start_paused>
                <service>/world/car_world/control</service>
                <stats_topic>/world/car_world/stats</stats_topic>
            </plugin>

            <!-- World statistics -->
            <plugin filename="WorldStats" name="World stats">
                <ignition-gui>
                <title>World stats</title>
                <property type="bool" key="showTitleBar">false</property>
                <property type="bool" key="resizable">false</property>
                <property type="double" key="height">110</property>
                <property type="double" key="width">290</property>
                <property type="double" key="z">1</property>

                <property type="string" key="state">floating</property>
                <anchors target="3D View">
                    <line own="right" target="right"/>
                    <line own="bottom" target="bottom"/>
                </anchors>
                </ignition-gui>

                <sim_time>true</sim_time>
                <real_time>true</real_time>
                <real_time_factor>true</real_time_factor>
                <iterations>true</iterations>
                <topic>/world/car_world/stats</topic>

            </plugin>

            <!-- Entity tree -->
            <plugin filename="EntityTree" name="Entity tree">
            </plugin>

			<plugin filename="KeyPublisher" name="Key Publisher"/>

        </gui>

        <light type="directional" name="sun">
            <cast_shadows>true</cast_shadows>
            <pose>0 0 10 0 0 0</pose>
            <diffuse>0.8 0.8 0.8 1</diffuse>
            <specular>0.2 0.2 0.2 1</specular>
            <attenuation>
                <range>1000</range>
                <constant>0.9</constant>
                <linear>0.01</linear>
                <quadratic>0.001</quadratic>
            </attenuation>
            <direction>-0.5 0.1 -0.9</direction>
        </light>


    <model name='rovcompleteversion'>
      <link name='base_link'>
        <inertial>
          <pose>-0.001403 0.14623 0.002883 0 -0 0</pose>
          <mass>19.341</mass>
          <inertia>
            <ixx>0.15242</ixx>
            <ixy>-2.6993e-07</ixy>
            <ixz>1.6606e-07</ixz>
            <iyy>0.16317</iyy>
            <iyz>0.000603</iyz>
            <izz>0.079219</izz>
          </inertia>
        </inertial>
        <self_collide>0</self_collide>
        <enable_wind>0</enable_wind>
        <kinematic>0</kinematic>
        <pose>0 0 0 0 -0 0</pose>
        <visual name='base_link_visual'>
          <pose>0 0 0 0 -0 0</pose>
          <geometry>
            <mesh>
              <scale>1 1 1</scale>
              <uri>/home/saab/Desktop/ROV_test_ws/src/rovurdfv32inner/meshes/base_link.STL</uri>
            </mesh>
          </geometry>
          <material>
            <shader type='pixel'/>
            <emissive>0 0 0 1</emissive>
          </material>
          <transparency>0</transparency>
          <cast_shadows>1</cast_shadows>
        </visual>
        <collision name='base_link_collision'>
          <laser_retro>0</laser_retro>
          <max_contacts>10</max_contacts>
          <pose>0 0 0 0 -0 0</pose>
          <geometry>
            <mesh>
              <uri>/home/saab/Desktop/ROV_test_ws/src/rovurdfv32inner/meshes/base_link.STL</uri>
              <scale>1 1 1</scale>
            </mesh>
          </geometry>
          <surface>
            <friction>
              <ode>
                <mu>1</mu>
                <mu2>1</mu2>
                <fdir1>0 0 0</fdir1>
                <slip1>0</slip1>
                <slip2>0</slip2>
              </ode>
              <torsional>
                <coefficient>1</coefficient>
                <patch_radius>0</patch_radius>
                <surface_radius>0</surface_radius>
                <use_patch_radius>1</use_patch_radius>
                <ode>
                  <slip>0</slip>
                </ode>
              </torsional>
            </friction>
            <bounce>
              <restitution_coefficient>0</restitution_coefficient>
              <threshold>1e+06</threshold>
            </bounce>
            <contact>
              <collide_without_contact>0</collide_without_contact>
              <collide_without_contact_bitmask>1</collide_without_contact_bitmask>
              <collide_bitmask>1</collide_bitmask>
              <ode>
                <soft_cfm>0</soft_cfm>
                <soft_erp>0.2</soft_erp>
                <kp>1e+13</kp>
                <kd>1</kd>
                <max_vel>0.01</max_vel>
                <min_depth>0</min_depth>
              </ode>
              <bullet>
                <split_impulse>1</split_impulse>
                <split_impulse_penetration_threshold>-0.01</split_impulse_penetration_threshold>
                <soft_cfm>0</soft_cfm>
                <soft_erp>0.2</soft_erp>
                <kp>1e+13</kp>
                <kd>1</kd>
              </bullet>
            </contact>
          </surface>
        </collision>
        <visual name='visual'>
					<geometry>
						<mesh>
              <uri>/home/saab/Desktop/ROV_test_ws/src/rovurdfv32inner/meshes/base_link.STL</uri>
              <scale>1 1 1</scale>
            </mesh>
					</geometry>
					<material>
							<ambient>1.0 1.0 1.0 1</ambient>
							<diffuse>1.0 1.0 1.0 1</diffuse>
							<specular>1.0 1.0 1.0 1</specular>
					</material>
				</visual>
      </link>
      <link name='botLprop'>
        <pose>0.254 0.1645 0.15302 0 -0 0</pose>
        <inertial>
          <pose>2e-06 0 0.002301 0 -0 0</pose>
          <mass>0.0077397</mass>
          <inertia>
            <ixx>2.2059e-06</ixx>
            <ixy>1.0231e-09</ixy>
            <ixz>6.4975e-12</ixz>
            <iyy>2.2081e-06</iyy>
            <iyz>-2.7383e-11</iyz>
            <izz>3.2147e-06</izz>
          </inertia>
        </inertial>
        <self_collide>0</self_collide>
        <enable_wind>0</enable_wind>
        <kinematic>0</kinematic>
        <visual name='botLprop_visual'>
          <pose>0 0 0 0 -0 0</pose>
          <geometry>
            <mesh>
              <scale>1 1 1</scale>
              <uri>/home/saab/Desktop/ROV_test_ws/src/rovurdfv32inner/meshes/botLprop.STL</uri>
            </mesh>
          </geometry>
          <material>
            <shader type='pixel'/>
            <emissive>0 0 0 1</emissive>
          </material>
          <transparency>0</transparency>
          <cast_shadows>1</cast_shadows>
        </visual>
        <collision name='botLprop_collision'>
          <laser_retro>0</laser_retro>
          <max_contacts>10</max_contacts>
          <pose>0 0 0 0 -0 0</pose>
          <geometry>
            <mesh>
              <uri>/home/saab/Desktop/ROV_test_ws/src/rovurdfv32inner/meshes/botLprop.STL</uri>
              <scale>1 1 1</scale>
            </mesh>
          </geometry>
          <surface>
            <friction>
              <ode>
                <mu>1</mu>
                <mu2>1</mu2>
                <fdir1>0 0 0</fdir1>
                <slip1>0</slip1>
                <slip2>0</slip2>
              </ode>
              <torsional>
                <coefficient>1</coefficient>
                <patch_radius>0</patch_radius>
                <surface_radius>0</surface_radius>
                <use_patch_radius>1</use_patch_radius>
                <ode>
                  <slip>0</slip>
                </ode>
              </torsional>
            </friction>
            <bounce>
              <restitution_coefficient>0</restitution_coefficient>
              <threshold>1e+06</threshold>
            </bounce>
            <contact>
              <collide_without_contact>0</collide_without_contact>
              <collide_without_contact_bitmask>1</collide_without_contact_bitmask>
              <collide_bitmask>1</collide_bitmask>
              <ode>
                <soft_cfm>0</soft_cfm>
                <soft_erp>0.2</soft_erp>
                <kp>1e+13</kp>
                <kd>1</kd>
                <max_vel>0.01</max_vel>
                <min_depth>0</min_depth>
              </ode>
              <bullet>
                <split_impulse>1</split_impulse>
                <split_impulse_penetration_threshold>-0.01</split_impulse_penetration_threshold>
                <soft_cfm>0</soft_cfm>
                <soft_erp>0.2</soft_erp>
                <kp>1e+13</kp>
                <kd>1</kd>
              </bullet>
            </contact>
          </surface>
        </collision>
      </link>
      <link name='botRprop'>
        <pose>-0.254 0.1645 0.15302 0 -0 0</pose>
        <inertial>
          <pose>0 -2e-06 0.002301 0 -0 0</pose>
          <mass>0.0077399</mass>
          <inertia>
            <ixx>2.207e-06</ixx>
            <ixy>4.648e-10</ixy>
            <ixz>3.9716e-11</ixz>
            <iyy>2.2074e-06</iyy>
            <iyz>-4.4954e-11</iyz>
            <izz>3.2149e-06</izz>
          </inertia>
        </inertial>
        <self_collide>0</self_collide>
        <enable_wind>0</enable_wind>
        <kinematic>0</kinematic>
        <visual name='botRprop_visual'>
          <pose>0 0 0 0 -0 0</pose>
          <geometry>
            <mesh>
              <scale>1 1 1</scale>
              <uri>/home/saab/Desktop/ROV_test_ws/src/rovurdfv32inner/meshes/botRprop.STL</uri>
            </mesh>
          </geometry>
          <material>
            <shader type='pixel'/>
            <emissive>0 0 0 1</emissive>
          </material>
          <transparency>0</transparency>
          <cast_shadows>1</cast_shadows>
        </visual>
        <collision name='botRprop_collision'>
          <laser_retro>0</laser_retro>
          <max_contacts>10</max_contacts>
          <pose>0 0 0 0 -0 0</pose>
          <geometry>
            <mesh>
              <uri>/home/saab/Desktop/ROV_test_ws/src/rovurdfv32inner/meshes/botRprop.STL</uri>
              <scale>1 1 1</scale>
            </mesh>
          </geometry>
          <surface>
            <friction>
              <ode>
                <mu>1</mu>
                <mu2>1</mu2>
                <fdir1>0 0 0</fdir1>
                <slip1>0</slip1>
                <slip2>0</slip2>
              </ode>
              <torsional>
                <coefficient>1</coefficient>
                <patch_radius>0</patch_radius>
                <surface_radius>0</surface_radius>
                <use_patch_radius>1</use_patch_radius>
                <ode>
                  <slip>0</slip>
                </ode>
              </torsional>
            </friction>
            <bounce>
              <restitution_coefficient>0</restitution_coefficient>
              <threshold>1e+06</threshold>
            </bounce>
            <contact>
              <collide_without_contact>0</collide_without_contact>
              <collide_without_contact_bitmask>1</collide_without_contact_bitmask>
              <collide_bitmask>1</collide_bitmask>
              <ode>
                <soft_cfm>0</soft_cfm>
                <soft_erp>0.2</soft_erp>
                <kp>1e+13</kp>
                <kd>1</kd>
                <max_vel>0.01</max_vel>
                <min_depth>0</min_depth>
              </ode>
              <bullet>
                <split_impulse>1</split_impulse>
                <split_impulse_penetration_threshold>-0.01</split_impulse_penetration_threshold>
                <soft_cfm>0</soft_cfm>
                <soft_erp>0.2</soft_erp>
                <kp>1e+13</kp>
                <kd>1</kd>
              </bullet>
            </contact>
          </surface>
        </collision>
      </link>
      <link name='innerbotLprop'>
        <pose>0.16112 0.14138 0.113 -1.5708 -0 0.7854</pose>
        <inertial>
          <pose>-1e-06 -2e-06 0.002301 0 -0 0</pose>
          <mass>0.007741</mass>
          <inertia>
            <ixx>2.2061e-06</ixx>
            <ixy>-5.2045e-11</ixy>
            <ixz>1.3192e-11</ixz>
            <iyy>2.2089e-06</iyy>
            <iyz>-4.986e-11</iyz>
            <izz>3.2154e-06</izz>
          </inertia>
        </inertial>
        <self_collide>0</self_collide>
        <enable_wind>0</enable_wind>
        <kinematic>0</kinematic>
        <visual name='innerbotLprop_visual'>
          <pose>0 0 0 0 -0 0</pose>
          <geometry>
            <mesh>
              <scale>1 1 1</scale>
              <uri>/home/saab/Desktop/ROV_test_ws/src/rovurdfv32inner/meshes/innerbotLprop.STL</uri>
            </mesh>
          </geometry>
          <material>
            <shader type='pixel'/>
            <emissive>0 0 0 1</emissive>
          </material>
          <transparency>0</transparency>
          <cast_shadows>1</cast_shadows>
        </visual>
        <collision name='innerbotLprop_collision'>
          <laser_retro>0</laser_retro>
          <max_contacts>10</max_contacts>
          <pose>0 0 0 0 -0 0</pose>
          <geometry>
            <mesh>
              <uri>/home/saab/Desktop/ROV_test_ws/src/rovurdfv32inner/meshes/innerbotLprop.STL</uri>
              <scale>1 1 1</scale>
            </mesh>
          </geometry>
          <surface>
            <friction>
              <ode>
                <mu>1</mu>
                <mu2>1</mu2>
                <fdir1>0 0 0</fdir1>
                <slip1>0</slip1>
                <slip2>0</slip2>
              </ode>
              <torsional>
                <coefficient>1</coefficient>
                <patch_radius>0</patch_radius>
                <surface_radius>0</surface_radius>
                <use_patch_radius>1</use_patch_radius>
                <ode>
                  <slip>0</slip>
                </ode>
              </torsional>
            </friction>
            <bounce>
              <restitution_coefficient>0</restitution_coefficient>
              <threshold>1e+06</threshold>
            </bounce>
            <contact>
              <collide_without_contact>0</collide_without_contact>
              <collide_without_contact_bitmask>1</collide_without_contact_bitmask>
              <collide_bitmask>1</collide_bitmask>
              <ode>
                <soft_cfm>0</soft_cfm>
                <soft_erp>0.2</soft_erp>
                <kp>1e+13</kp>
                <kd>1</kd>
                <max_vel>0.01</max_vel>
                <min_depth>0</min_depth>
              </ode>
              <bullet>
                <split_impulse>1</split_impulse>
                <split_impulse_penetration_threshold>-0.01</split_impulse_penetration_threshold>
                <soft_cfm>0</soft_cfm>
                <soft_erp>0.2</soft_erp>
                <kp>1e+13</kp>
                <kd>1</kd>
              </bullet>
            </contact>
          </surface>
        </collision>
      </link>
      <link name='innerbotRprop'>
        <pose>-0.16112 0.14138 0.113 -1.5708 -0 -0.7854</pose>
        <inertial>
          <pose>-1e-06 -2e-06 0.002301 0 -0 0</pose>
          <mass>0.007741</mass>
          <inertia>
            <ixx>2.2061e-06</ixx>
            <ixy>-5.2045e-11</ixy>
            <ixz>1.3192e-11</ixz>
            <iyy>2.2089e-06</iyy>
            <iyz>-4.986e-11</iyz>
            <izz>3.2154e-06</izz>
          </inertia>
        </inertial>
        <self_collide>0</self_collide>
        <enable_wind>0</enable_wind>
        <kinematic>0</kinematic>
        <visual name='innerbotRprop_visual'>
          <pose>0 0 0 0 -0 0</pose>
          <geometry>
            <mesh>
              <scale>1 1 1</scale>
              <uri>/home/saab/Desktop/ROV_test_ws/src/rovurdfv32inner/meshes/innerbotRprop.STL</uri>
            </mesh>
          </geometry>
          <material>
            <shader type='pixel'/>
            <emissive>0 0 0 1</emissive>
          </material>
          <transparency>0</transparency>
          <cast_shadows>1</cast_shadows>
        </visual>
        <collision name='innerbotRprop_collision'>
          <laser_retro>0</laser_retro>
          <max_contacts>10</max_contacts>
          <pose>0 0 0 0 -0 0</pose>
          <geometry>
            <mesh>
              <uri>/home/saab/Desktop/ROV_test_ws/src/rovurdfv32inner/meshes/innerbotRprop.STL</uri>
              <scale>1 1 1</scale>
            </mesh>
          </geometry>
          <surface>
            <friction>
              <ode>
                <mu>1</mu>
                <mu2>1</mu2>
                <fdir1>0 0 0</fdir1>
                <slip1>0</slip1>
                <slip2>0</slip2>
              </ode>
              <torsional>
                <coefficient>1</coefficient>
                <patch_radius>0</patch_radius>
                <surface_radius>0</surface_radius>
                <use_patch_radius>1</use_patch_radius>
                <ode>
                  <slip>0</slip>
                </ode>
              </torsional>
            </friction>
            <bounce>
              <restitution_coefficient>0</restitution_coefficient>
              <threshold>1e+06</threshold>
            </bounce>
            <contact>
              <collide_without_contact>0</collide_without_contact>
              <collide_without_contact_bitmask>1</collide_without_contact_bitmask>
              <collide_bitmask>1</collide_bitmask>
              <ode>
                <soft_cfm>0</soft_cfm>
                <soft_erp>0.2</soft_erp>
                <kp>1e+13</kp>
                <kd>1</kd>
                <max_vel>0.01</max_vel>
                <min_depth>0</min_depth>
              </ode>
              <bullet>
                <split_impulse>1</split_impulse>
                <split_impulse_penetration_threshold>-0.01</split_impulse_penetration_threshold>
                <soft_cfm>0</soft_cfm>
                <soft_erp>0.2</soft_erp>
                <kp>1e+13</kp>
                <kd>1</kd>
              </bullet>
            </contact>
          </surface>
        </collision>
      </link>
      <link name='innertopLprop'>
        <pose>0.16112 -0.13638 0.113 1.5708 -0 -0.7854</pose>
        <inertial>
          <pose>-2e-06 -0 0.002302 0 -0 0</pose>
          <mass>0.0077403</mass>
          <inertia>
            <ixx>2.2064e-06</ixx>
            <ixy>1.1946e-09</ixy>
            <ixz>-1.4241e-11</ixz>
            <iyy>2.2082e-06</iyy>
            <iyz>-2.0704e-11</iyz>
            <izz>3.2151e-06</izz>
          </inertia>
        </inertial>
        <self_collide>0</self_collide>
        <enable_wind>0</enable_wind>
        <kinematic>0</kinematic>
        <visual name='innertopLprop_visual'>
          <pose>0 0 0 0 -0 0</pose>
          <geometry>
            <mesh>
              <scale>1 1 1</scale>
              <uri>/home/saab/Desktop/ROV_test_ws/src/rovurdfv32inner/meshes/innertopLprop.STL</uri>
            </mesh>
          </geometry>
          <material>
            <shader type='pixel'/>
            <emissive>0 0 0 1</emissive>
          </material>
          <transparency>0</transparency>
          <cast_shadows>1</cast_shadows>
        </visual>
        <collision name='innertopLprop_collision'>
          <laser_retro>0</laser_retro>
          <max_contacts>10</max_contacts>
          <pose>0 0 0 0 -0 0</pose>
          <geometry>
            <mesh>
              <uri>/home/saab/Desktop/ROV_test_ws/src/rovurdfv32inner/meshes/innertopLprop.STL</uri>
              <scale>1 1 1</scale>
            </mesh>
          </geometry>
          <surface>
            <friction>
              <ode>
                <mu>1</mu>
                <mu2>1</mu2>
                <fdir1>0 0 0</fdir1>
                <slip1>0</slip1>
                <slip2>0</slip2>
              </ode>
              <torsional>
                <coefficient>1</coefficient>
                <patch_radius>0</patch_radius>
                <surface_radius>0</surface_radius>
                <use_patch_radius>1</use_patch_radius>
                <ode>
                  <slip>0</slip>
                </ode>
              </torsional>
            </friction>
            <bounce>
              <restitution_coefficient>0</restitution_coefficient>
              <threshold>1e+06</threshold>
            </bounce>
            <contact>
              <collide_without_contact>0</collide_without_contact>
              <collide_without_contact_bitmask>1</collide_without_contact_bitmask>
              <collide_bitmask>1</collide_bitmask>
              <ode>
                <soft_cfm>0</soft_cfm>
                <soft_erp>0.2</soft_erp>
                <kp>1e+13</kp>
                <kd>1</kd>
                <max_vel>0.01</max_vel>
                <min_depth>0</min_depth>
              </ode>
              <bullet>
                <split_impulse>1</split_impulse>
                <split_impulse_penetration_threshold>-0.01</split_impulse_penetration_threshold>
                <soft_cfm>0</soft_cfm>
                <soft_erp>0.2</soft_erp>
                <kp>1e+13</kp>
                <kd>1</kd>
              </bullet>
            </contact>
          </surface>
        </collision>
      </link>
      <link name='innertopRprop'>
        <pose>-0.16112 -0.13638 0.113 1.5708 -0 0.7854</pose>
        <inertial>
          <pose>-2e-06 -0 0.002302 0 -0 0</pose>
          <mass>0.0077403</mass>
          <inertia>
            <ixx>2.2064e-06</ixx>
            <ixy>1.1946e-09</ixy>
            <ixz>-1.4241e-11</ixz>
            <iyy>2.2082e-06</iyy>
            <iyz>-2.0704e-11</iyz>
            <izz>3.2151e-06</izz>
          </inertia>
        </inertial>
        <self_collide>0</self_collide>
        <enable_wind>0</enable_wind>
        <kinematic>0</kinematic>
        <visual name='innertopRprop_visual'>
          <pose>0 0 0 0 -0 0</pose>
          <geometry>
            <mesh>
              <scale>1 1 1</scale>
              <uri>/home/saab/Desktop/ROV_test_ws/src/rovurdfv32inner/meshes/innertopRprop.STL</uri>
            </mesh>
          </geometry>
          <material>
            <shader type='pixel'/>
            <emissive>0 0 0 1</emissive>
          </material>
          <transparency>0</transparency>
          <cast_shadows>1</cast_shadows>
        </visual>
        <collision name='innertopRprop_collision'>
          <laser_retro>0</laser_retro>
          <max_contacts>10</max_contacts>
          <pose>0 0 0 0 -0 0</pose>
          <geometry>
            <mesh>
              <uri>/home/saab/Desktop/ROV_test_ws/src/rovurdfv32inner/meshes/innertopRprop.STL</uri>
              <scale>1 1 1</scale>
            </mesh>
          </geometry>
          <surface>
            <friction>
              <ode>
                <mu>1</mu>
                <mu2>1</mu2>
                <fdir1>0 0 0</fdir1>
                <slip1>0</slip1>
                <slip2>0</slip2>
              </ode>
              <torsional>
                <coefficient>1</coefficient>
                <patch_radius>0</patch_radius>
                <surface_radius>0</surface_radius>
                <use_patch_radius>1</use_patch_radius>
                <ode>
                  <slip>0</slip>
                </ode>
              </torsional>
            </friction>
            <bounce>
              <restitution_coefficient>0</restitution_coefficient>
              <threshold>1e+06</threshold>
            </bounce>
            <contact>
              <collide_without_contact>0</collide_without_contact>
              <collide_without_contact_bitmask>1</collide_without_contact_bitmask>
              <collide_bitmask>1</collide_bitmask>
              <ode>
                <soft_cfm>0</soft_cfm>
                <soft_erp>0.2</soft_erp>
                <kp>1e+13</kp>
                <kd>1</kd>
                <max_vel>0.01</max_vel>
                <min_depth>0</min_depth>
              </ode>
              <bullet>
                <split_impulse>1</split_impulse>
                <split_impulse_penetration_threshold>-0.01</split_impulse_penetration_threshold>
                <soft_cfm>0</soft_cfm>
                <soft_erp>0.2</soft_erp>
                <kp>1e+13</kp>
                <kd>1</kd>
              </bullet>
            </contact>
          </surface>
        </collision>
      </link>
      <link name='topLprop'>
        <pose>0.254 -0.1645 0.15302 0 -0 0</pose>
        <inertial>
          <pose>-2e-06 -0 0.002301 0 -0 0</pose>
          <mass>0.0077397</mass>
          <inertia>
            <ixx>2.2068e-06</ixx>
            <ixy>7.4022e-11</ixy>
            <ixz>-1.0743e-11</ixz>
            <iyy>2.2073e-06</iyy>
            <iyz>2.5892e-11</iyz>
            <izz>3.2147e-06</izz>
          </inertia>
        </inertial>
        <self_collide>0</self_collide>
        <enable_wind>0</enable_wind>
        <kinematic>0</kinematic>
        <visual name='topLprop_visual'>
          <pose>0 0 0 0 -0 0</pose>
          <geometry>
            <mesh>
              <scale>1 1 1</scale>
              <uri>/home/saab/Desktop/ROV_test_ws/src/rovurdfv32inner/meshes/topLprop.STL</uri>
            </mesh>
          </geometry>
          <material>
            <shader type='pixel'/>
            <emissive>0 0 0 1</emissive>
          </material>
          <transparency>0</transparency>
          <cast_shadows>1</cast_shadows>
        </visual>
        <collision name='topLprop_collision'>
          <laser_retro>0</laser_retro>
          <max_contacts>10</max_contacts>
          <pose>0 0 0 0 -0 0</pose>
          <geometry>
            <mesh>
              <uri>/home/saab/Desktop/ROV_test_ws/src/rovurdfv32inner/meshes/topLprop.STL</uri>
              <scale>1 1 1</scale>
            </mesh>
          </geometry>
          <surface>
            <friction>
              <ode>
                <mu>1</mu>
                <mu2>1</mu2>
                <fdir1>0 0 0</fdir1>
                <slip1>0</slip1>
                <slip2>0</slip2>
              </ode>
              <torsional>
                <coefficient>1</coefficient>
                <patch_radius>0</patch_radius>
                <surface_radius>0</surface_radius>
                <use_patch_radius>1</use_patch_radius>
                <ode>
                  <slip>0</slip>
                </ode>
              </torsional>
            </friction>
            <bounce>
              <restitution_coefficient>0</restitution_coefficient>
              <threshold>1e+06</threshold>
            </bounce>
            <contact>
              <collide_without_contact>0</collide_without_contact>
              <collide_without_contact_bitmask>1</collide_without_contact_bitmask>
              <collide_bitmask>1</collide_bitmask>
              <ode>
                <soft_cfm>0</soft_cfm>
                <soft_erp>0.2</soft_erp>
                <kp>1e+13</kp>
                <kd>1</kd>
                <max_vel>0.01</max_vel>
                <min_depth>0</min_depth>
              </ode>
              <bullet>
                <split_impulse>1</split_impulse>
                <split_impulse_penetration_threshold>-0.01</split_impulse_penetration_threshold>
                <soft_cfm>0</soft_cfm>
                <soft_erp>0.2</soft_erp>
                <kp>1e+13</kp>
                <kd>1</kd>
              </bullet>
            </contact>
          </surface>
        </collision>
      </link>
      <link name='topRprop'>
        <pose>-0.254 -0.1645 0.15302 0 -0 0</pose>
        <inertial>
          <pose>0 -2e-06 0.002301 0 -0 0</pose>
          <mass>0.0077399</mass>
          <inertia>
            <ixx>2.207e-06</ixx>
            <ixy>4.5574e-10</ixy>
            <ixz>3.9272e-11</ixz>
            <iyy>2.2073e-06</iyy>
            <iyz>-4.478e-11</iyz>
            <izz>3.2149e-06</izz>
          </inertia>
        </inertial>
        <self_collide>0</self_collide>
        <enable_wind>0</enable_wind>
        <kinematic>0</kinematic>
        <visual name='topRprop_visual'>
          <pose>0 0 0 0 -0 0</pose>
          <geometry>
            <mesh>
              <scale>1 1 1</scale>
              <uri>/home/saab/Desktop/ROV_test_ws/src/rovurdfv32inner/meshes/topRprop.STL</uri>
            </mesh>
          </geometry>
          <material>
            <shader type='pixel'/>
            <emissive>0 0 0 1</emissive>
          </material>
          <transparency>0</transparency>
          <cast_shadows>1</cast_shadows>
        </visual>
        <collision name='topRprop_collision'>
          <laser_retro>0</laser_retro>
          <max_contacts>10</max_contacts>
          <pose>0 0 0 0 -0 0</pose>
          <geometry>
            <mesh>
              <uri>/home/saab/Desktop/ROV_test_ws/src/rovurdfv32inner/meshes/topRprop.STL</uri>
              <scale>1 1 1</scale>
            </mesh>
          </geometry>
          <surface>
            <friction>
              <ode>
                <mu>1</mu>
                <mu2>1</mu2>
                <fdir1>0 0 0</fdir1>
                <slip1>0</slip1>
                <slip2>0</slip2>
              </ode>
              <torsional>
                <coefficient>1</coefficient>
                <patch_radius>0</patch_radius>
                <surface_radius>0</surface_radius>
                <use_patch_radius>1</use_patch_radius>
                <ode>
                  <slip>0</slip>
                </ode>
              </torsional>
            </friction>
            <bounce>
              <restitution_coefficient>0</restitution_coefficient>
              <threshold>1e+06</threshold>
            </bounce>
            <contact>
              <collide_without_contact>0</collide_without_contact>
              <collide_without_contact_bitmask>1</collide_without_contact_bitmask>
              <collide_bitmask>1</collide_bitmask>
              <ode>
                <soft_cfm>0</soft_cfm>
                <soft_erp>0.2</soft_erp>
                <kp>1e+13</kp>
                <kd>1</kd>
                <max_vel>0.01</max_vel>
                <min_depth>0</min_depth>
              </ode>
              <bullet>
                <split_impulse>1</split_impulse>
                <split_impulse_penetration_threshold>-0.01</split_impulse_penetration_threshold>
                <soft_cfm>0</soft_cfm>
                <soft_erp>0.2</soft_erp>
                <kp>1e+13</kp>
                <kd>1</kd>
              </bullet>
            </contact>
          </surface>
        </collision>
      </link>
      <joint name='base_link_JOINT_botL' type='revolute'>
        <parent>base_link</parent>
        <child>botLprop</child>
        <pose>0 0 0 0 -0 0</pose>
        <axis>
          <xyz>0 0 1</xyz>
          <limit>
            <lower>-1.79769e+308</lower>
            <upper>1.79769e+308</upper>
            <effort>-1</effort>
            <velocity>-1</velocity>
          </limit>
          <dynamics>
            <spring_reference>0</spring_reference>
            <spring_stiffness>0</spring_stiffness>
            <damping>0</damping>
            <friction>0</friction>
          </dynamics>
        </axis>
        <physics>
          <ode>
            <limit>
              <cfm>0</cfm>
              <erp>0.2</erp>
            </limit>
            <suspension>
              <cfm>0</cfm>
              <erp>0.2</erp>
            </suspension>
          </ode>
        </physics>
      </joint>
      <joint name='base_link_JOINT_botR' type='revolute'>
        <parent>base_link</parent>
        <child>botRprop</child>
        <pose>0 0 0 0 -0 0</pose>
        <axis>
          <xyz>0 0 1</xyz>
          <limit>
            <lower>-1.79769e+308</lower>
            <upper>1.79769e+308</upper>
            <effort>-1</effort>
            <velocity>-1</velocity>
          </limit>
          <dynamics>
            <spring_reference>0</spring_reference>
            <spring_stiffness>0</spring_stiffness>
            <damping>0</damping>
            <friction>0</friction>
          </dynamics>
        </axis>
        <physics>
          <ode>
            <limit>
              <cfm>0</cfm>
              <erp>0.2</erp>
            </limit>
            <suspension>
              <cfm>0</cfm>
              <erp>0.2</erp>
            </suspension>
          </ode>
        </physics>
      </joint>
      <joint name='base_link_JOINT_innerbotL' type='revolute'>
        <parent>base_link</parent>
        <child>innerbotLprop</child>
        <pose>0 0 0 0 -0 0</pose>
        <axis>
          <xyz>0 0 1</xyz>
          <limit>
            <lower>-1.79769e+308</lower>
            <upper>1.79769e+308</upper>
            <effort>-1</effort>
            <velocity>-1</velocity>
          </limit>
          <dynamics>
            <spring_reference>0</spring_reference>
            <spring_stiffness>0</spring_stiffness>
            <damping>0</damping>
            <friction>0</friction>
          </dynamics>
        </axis>
        <physics>
          <ode>
            <limit>
              <cfm>0</cfm>
              <erp>0.2</erp>
            </limit>
            <suspension>
              <cfm>0</cfm>
              <erp>0.2</erp>
            </suspension>
          </ode>
        </physics>
      </joint>
      <joint name='base_link_JOINT_innerbotR' type='revolute'>
        <parent>base_link</parent>
        <child>innerbotRprop</child>
        <pose>0 0 0 0 -0 0</pose>
        <axis>
          <xyz>0 0 1</xyz>
          <limit>
            <lower>-1.79769e+308</lower>
            <upper>1.79769e+308</upper>
            <effort>-1</effort>
            <velocity>-1</velocity>
          </limit>
          <dynamics>
            <spring_reference>0</spring_reference>
            <spring_stiffness>0</spring_stiffness>
            <damping>0</damping>
            <friction>0</friction>
          </dynamics>
        </axis>
        <physics>
          <ode>
            <limit>
              <cfm>0</cfm>
              <erp>0.2</erp>
            </limit>
            <suspension>
              <cfm>0</cfm>
              <erp>0.2</erp>
            </suspension>
          </ode>
        </physics>
      </joint>
      <joint name='base_link_JOINT_innertopL' type='revolute'>
        <parent>base_link</parent>
        <child>innertopLprop</child>
        <pose>0 0 0 0 -0 0</pose>
        <axis>
          <xyz>0 0 1</xyz>
          <limit>
            <lower>-1.79769e+308</lower>
            <upper>1.79769e+308</upper>
            <effort>-1</effort>
            <velocity>-1</velocity>
          </limit>
          <dynamics>
            <spring_reference>0</spring_reference>
            <spring_stiffness>0</spring_stiffness>
            <damping>0</damping>
            <friction>0</friction>
          </dynamics>
        </axis>
        <physics>
          <ode>
            <limit>
              <cfm>0</cfm>
              <erp>0.2</erp>
            </limit>
            <suspension>
              <cfm>0</cfm>
              <erp>0.2</erp>
            </suspension>
          </ode>
        </physics>
      </joint>
      <joint name='base_link_JOINT_innertopR' type='revolute'>
        <parent>base_link</parent>
        <child>innertopRprop</child>
        <pose>0 0 0 0 -0 0</pose>
        <axis>
          <xyz>0 0 1</xyz>
          <limit>
            <lower>-1.79769e+308</lower>
            <upper>1.79769e+308</upper>
            <effort>-1</effort>
            <velocity>-1</velocity>
          </limit>
          <dynamics>
            <spring_reference>0</spring_reference>
            <spring_stiffness>0</spring_stiffness>
            <damping>0</damping>
            <friction>0</friction>
          </dynamics>
        </axis>
        <physics>
          <ode>
            <limit>
              <cfm>0</cfm>
              <erp>0.2</erp>
            </limit>
            <suspension>
              <cfm>0</cfm>
              <erp>0.2</erp>
            </suspension>
          </ode>
        </physics>
      </joint>
      <joint name='base_link_JOINT_topL' type='revolute'>
        <parent>base_link</parent>
        <child>topLprop</child>
        <pose>0 0 0 0 -0 0</pose>
        <axis>
          <xyz>0 0 1</xyz>
          <limit>
            <lower>-1.79769e+308</lower>
            <upper>1.79769e+308</upper>
            <effort>-1</effort>
            <velocity>-1</velocity>
          </limit>
          <dynamics>
            <spring_reference>0</spring_reference>
            <spring_stiffness>0</spring_stiffness>
            <damping>0</damping>
            <friction>0</friction>
          </dynamics>
        </axis>
        <physics>
          <ode>
            <limit>
              <cfm>0</cfm>
              <erp>0.2</erp>
            </limit>
            <suspension>
              <cfm>0</cfm>
              <erp>0.2</erp>
            </suspension>
          </ode>
        </physics>
      </joint>
      <joint name='base_link_JOINT_topR' type='revolute'>
        <parent>base_link</parent>
        <child>topRprop</child>
        <pose>0 0 0 0 -0 0</pose>
        <axis>
          <xyz>0 0 1</xyz>
          <limit>
            <lower>-1.79769e+308</lower>
            <upper>1.79769e+308</upper>
            <effort>-1</effort>
            <velocity>-1</velocity>
          </limit>
          <dynamics>
            <spring_reference>0</spring_reference>
            <spring_stiffness>0</spring_stiffness>
            <damping>0</damping>
            <friction>0</friction>
          </dynamics>
        </axis>
        <physics>
          <ode>
            <limit>
              <cfm>0</cfm>
              <erp>0.2</erp>
            </limit>
            <suspension>
              <cfm>0</cfm>
              <erp>0.2</erp>
            </suspension>
          </ode>
        </physics>
      </joint>

      <!--joints-->
      <plugin
        filename="ignition-gazebo-hydrodynamics-system"
        name="ignition::gazebo::systems::Hydrodynamics">
        <link_name>base_link</link_name>
        <xDotU>0</xDotU>
        <yDotV>0</yDotV>
        <zDotW>0</zDotW>
        <kDotP>0</kDotP>
        <mDotQ>0</mDotQ>
        <nDotR>0</nDotR>
        <xUU>0</xUU>
        <xU>0</xU>
        <yVV>0.27</yVV>
        <yV>0</yV>
        <zWW>0</zWW>
        <zW>0</zW>
        <kPP>0</kPP>
        <kP>0</kP>
        <mQQ>0</mQQ>
        <mQ>0</mQ>
        <nRR>0</nRR>
        <nR>0</nR>
      </plugin>


      <!--joints
      <plugin
        filename="ignition-gazebo-hydrodynamics-system"
        name="ignition::gazebo::systems::Hydrodynamics">
        <link_name>base_link</link_name>
        <xDotU>-4.876161</xDotU>
        <yDotV>-126.324739</yDotV>
        <zDotW>-126.324739</zDotW>
        <kDotP>0</kDotP>
        <mDotQ>-33.46</mDotQ>
        <nDotR>-33.46</nDotR>
        <xUU>-6.2282</xUU>
        <xU>0</xU>
        <yVV>-601.27</yVV>
        <yV>0</yV>
        <zWW>-601.27</zWW>
        <zW>0</zW>
        <kPP>-0.1916</kPP>
        <kP>0</kP>
        <mQQ>-632.698957</mQQ>
        <mQ>0</mQ>
        <nRR>-632.698957</nRR>
        <nR>0</nR>
      </plugin>        
      -->

      <static>0</static>
      <allow_auto_disable>1</allow_auto_disable>
    </model>
  </world>
</sdf>
